Workbook

Sheet Cover
B2: Excel Practical Assignment — Section 7: Pivot Table A-2-Z
B4: Dataset used: Superstore Sales (Raw Data sheet, 60 sample transactions incl. some blank Region cells)
B5: PivotTable-style summaries below use SUMIFS/COUNTIFS/AVERAGEIFS so they mirror a real PivotTable
B6: and recalculate live; each sheet explains how to build the actual interactive PivotTable in Excel.
B8: Sheets in this workbook:
B9: Raw Data -> Shared source table used by every PivotTable-style sheet below
B10: 1. Getting Started -> Sum/Count/Average by Category, a Region filter, and PivotTable component basics
B11: 2. Grouping & Multi Tables -> Sales by Month & Quarter, two independent tables side by side
B12: 3. Date & Blank Grouping -> Sales by Year and Year-Quarter, plus handling a "(blank)" Region group
B13: 4. Custom Grouping & CF -> a business-defined custom group, plus Color Scale / Data Bar / Icon Set CF

Sheet Raw Data
A1: Source dataset for Section 7 (Superstore sample) — used as the PivotTable source range on every sheet
A4: Product Name | B4: Category | C4: Region | D4: Order Date | E4: Sales | F4: Profit | G4: Quantity
A5: Bush Somerset Collection Boo | B5: Furniture | C5: South | D5: 42682 | E5: 261.96 | F5: 41.9136 | G5: 2
A6: Hon Deluxe Fabric Upholstere | B6: Furniture | C6: South | D6: 42682 | E6: 731.94 | F6: 219.582 | G6: 3
A7: Self-Adhesive Address Labels | B7: Office Supplies | C7: West | D7: 42533 | E7: 14.62 | F7: 6.8714 | G7: 2
A8: Bretford CR4500 Series Slim | B8: Furniture | C8: South | D8: 42288 | E8: 957.5775 | F8: -383.031 | G8: 5
A9: Eldon Fold 'N Roll Cart Syst | B9: Office Supplies | C9: South | D9: 42288 | E9: 22.368 | F9: 2.5164 | G9: 2
A10: Eldon Expressions Wood and P | B10: Furniture | C10: West | D10: 41799 | E10: 48.86 | F10: 14.1694 | G10: 7
A11: Newell 322 | B11: Office Supplies | C11: West | D11: 41799 | E11: 7.28 | F11: 1.9656 | G11: 4
A12: Mitel 5320 IP Phone VoIP pho | B12: Technology | C12: West | D12: 41799 | E12: 907.152 | F12: 90.7152 | G12: 6
A13: DXL Angle-View Binders with | B13: Office Supplies | C13: West | D13: 41799 | E13: 18.504 | F13: 5.7825 | G13: 3
A14: Belkin F5C206VTEL 6 Outlet S | B14: Office Supplies | C14: West | D14: 41799 | E14: 114.9 | F14: 34.47 | G14: 5
A15: Chromcraft Rectangular Confe | B15: Furniture | D15: 41799 | E15: 1706.184 | F15: 85.3092 | G15: 9
A16: Konftel 250 Conference phone | B16: Technology | C16: West | D16: 41799 | E16: 911.424 | F16: 68.3568 | G16: 4
A17: Xerox 1967 | B17: Office Supplies | C17: South | D17: 42840 | E17: 15.552 | F17: 5.4432 | G17: 3
A18: Fellowes PB200 Plastic Comb | B18: Office Supplies | C18: West | D18: 42709 | E18: 407.976 | F18: 132.5922 | G18: 3
A19: Holmes Replacement Filter fo | B19: Office Supplies | C19: Central | D19: 42330 | E19: 68.81 | F19: -123.858 | G19: 5
A20: Storex DuraTech Recycled Pla | B20: Office Supplies | C20: Central | D20: 42330 | E20: 2.544 | F20: -3.816 | G20: 3
A21: Stur-D-Stor Shelving, Vertic | B21: Office Supplies | C21: Central | D21: 41954 | E21: 665.88 | F21: 13.3176 | G21: 6
A22: Fellowes Super Stor/Drawer | B22: Office Supplies | C22: West | D22: 41772 | E22: 55.5 | F22: 9.99 | G22: 2
A23: Newell 341 | B23: Office Supplies | C23: West | D23: 41878 | E23: 8.56 | F23: 2.4824 | G23: 2
A24: Cisco SPA 501G IP Phone | B24: Technology | C24: West | D24: 41878 | E24: 213.48 | F24: 16.011 | G24: 3
A25: Wilson Jones Hanging View Bi | B25: Office Supplies | C25: West | D25: 41878 | E25: 22.72 | F25: 7.384 | G25: 4
A26: Newell 318 | B26: Office Supplies | D26: 42713 | E26: 19.46 | F26: 5.0596 | G26: 7
A27: Acco Six-Outlet Power Strip, | B27: Office Supplies | C27: Central | D27: 42713 | E27: 60.34 | F27: 15.6884 | G27: 7
A28: Global Deluxe Stacking Chair | B28: Furniture | C28: East | D28: 42932 | E28: 71.372 | F28: -1.0196 | G28: 2
A29: Bretford CR4500 Series Slim | B29: Furniture | C29: West | D29: 42272 | E29: 1044.63 | F29: 240.2649 | G29: 3
A30: Wilson Jones Active Use Bind | B30: Office Supplies | C30: West | D30: 42385 | E30: 11.648 | F30: 4.2224 | G30: 2
A31: Imation 8GB Mini TravelDrive | B31: Technology | C31: West | D31: 42385 | E31: 90.57 | F31: 11.7741 | G31: 3
A32: Riverside Palais Royal Lawye | B32: Furniture | C32: East | D32: 42264 | E32: 3083.43 | F32: -1665.0522 | G32: 7
A33: Avery Recycled Flexi-View Co | B33: Office Supplies | C33: East | D33: 42264 | E33: 9.618 | F33: -7.0532 | G33: 2
A34: Howard Miller 13-3/4" Diamet | B34: Furniture | C34: East | D34: 42264 | E34: 124.2 | F34: 15.525 | G34: 3
A35: Poly String Tie Envelopes | B35: Office Supplies | C35: East | D35: 42264 | E35: 3.264 | F35: 1.1016 | G35: 2
A36: BOSTON Model 1800 Electric P | B36: Office Supplies | C36: East | D36: 42264 | E36: 86.304 | F36: 9.7092 | G36: 6
A37: Acco Pressboard Covers with | B37: Office Supplies | D37: 42264 | E37: 6.858 | F37: -5.715 | G37: 6
A38: Lumber Crayons | B38: Office Supplies | C38: East | D38: 42264 | E38: 15.76 | F38: 3.546 | G38: 2
A39: Easy-staple paper | B39: Office Supplies | C39: Central | D39: 43027 | E39: 29.472 | F39: 9.9468 | G39: 3
A40: GE 30524EE4 | B40: Technology | C40: Central | D40: 42712 | E40: 1097.544 | F40: 123.4737 | G40: 7
A41: Electrix Architect's Clamp-O | B41: Furniture | C41: Central | D41: 42712 | E41: 190.92 | F41: -147.963 | G41: 5
A42: #10-4 1/8" x 9 1/2" Premium | B42: Office Supplies | C42: Central | D42: 42365 | E42: 113.328 | F42: 35.415 | G42: 9
...

Sheet 1. Getting Started
A1: Section 7.1 — Getting Started with Pivot Table
A2: Tasks 1-5: Sales dataset, Insert PivotTable, Add fields, Apply a filter, Explain components
A4: Task 1-3: PivotTable-style summary — Sum of Sales, Count of Orders, Average Sale by Category
A5: Row Labels (Category) | B5: Sum of Sales | C5: Count of Orders | D5: Average Sale
A6: Furniture | B6: =SUMIFS('Raw Data'!$E$5:$E$64,'Raw Data'!$B$5:$B$64,A6) -> 9381.0907 | C6: =COUNTIFS('Raw Data'!$B$5:$B$64,A6) -> 15 | D6: =AVERAGEIFS('Raw Data'!$E$5:$E$64,'Raw Data'!$B$5:$B$64,A6) -> 625.40605
A7: Office Supplies | B7: =SUMIFS('Raw Data'!$E$5:$E$64,'Raw Data'!$B$5:$B$64,A7) -> 2568.362 | C7: =COUNTIFS('Raw Data'!$B$5:$B$64,A7) -> 33 | D7: =AVERAGEIFS('Raw Data'!$E$5:$E$64,'Raw Data'!$B$5:$B$64,A7) -> 77.829152
A8: Technology | B8: =SUMIFS('Raw Data'!$E$5:$E$64,'Raw Data'!$B$5:$B$64,A8) -> 4911.236 | C8: =COUNTIFS('Raw Data'!$B$5:$B$64,A8) -> 12 | D8: =AVERAGEIFS('Raw Data'!$E$5:$E$64,'Raw Data'!$B$5:$B$64,A8) -> 409.26967
A9: Grand Total | B9: =SUM(B6:B8) -> 16860.689 | C9: =SUM(C6:C8) -> 60
A11: Task 4: Apply a filter — same summary, filtered to Region = "West" only
A12: Row Labels (Category) | B12: Sum of Sales (Region = West)
A13: Furniture | B13: =SUMIFS('Raw Data'!$E$5:$E$64,'Raw Data'!$B$5:$B$64,A13,'Raw Data'!$C$5:$C$64,"West") -> 1093.49
A14: Office Supplies | B14: =SUMIFS('Raw Data'!$E$5:$E$64,'Raw Data'!$B$5:$B$64,A14,'Raw Data'!$C$5:$C$64,"West") -> 739.588
A15: Technology | B15: =SUMIFS('Raw Data'!$E$5:$E$64,'Raw Data'!$B$5:$B$64,A15,'Raw Data'!$C$5:$C$64,"West") -> 2122.626

Sheet 2. Grouping & Multi Tables
A1: Section 7.2 — Grouping and Multiple Tables in Pivot Table
A2: Tasks 1-5: Group by month, Multiple tables, Group by quarter/year, Compare products across regions, Benefits
A4: Task 1 & 3: Sales grouped by Month, and by Quarter
A5: Month | B5: Sum of Sales | C5: Quarter | D5: Sum of Sales
A6: Jan | B6: =SUMPRODUCT(('Raw Data'!$D$5:$D$64>=DATE(2016,1,1))*('Raw Data'!$D$5:$D$64<DATE(2016,1+1,1))*'Raw Data'!$E$5:$E$64)+SUMPRODUCT(('Raw Data'!$D$5:$D$64>=DATE(2015,1,1))*('Raw Data'!$D$5:$D$64<DATE(2015,1+1,1))*'Raw Data'!$E$5:$E$64)+SUMPRODUCT(('Raw Data'!$D$5:$D$64>=DATE(2014,1,1))*('Raw Data'!$D$5:$D$64<DATE(2014,1+1,1))*'Raw Data'!$E$5:$E$64)+SUMPRODUCT(('Raw Data'!$D$5:$D$64>=DATE(2017,1,1))*('Raw Data'!$D$5:$D$64<DATE(2017,1+1,1))*'Raw Data'!$E$5:$E$64) -> 102.218 | C6: Q1 | D6: =SUM(B6:B8) -> 165.658
A7: Feb | B7: =SUMPRODUCT(('Raw Data'!$D$5:$D$64>=DATE(2016,2,1))*('Raw Data'!$D$5:$D$64<DATE(2016,2+1,1))*'Raw Data'!$E$5:$E$64)+SUMPRODUCT(('Raw Data'!$D$5:$D$64>=DATE(2015,2,1))*('Raw Data'!$D$5:$D$64<DATE(2015,2+1,1))*'Raw Data'!$E$5:$E$64)+SUMPRODUCT(('Raw Data'!$D$5:$D$64>=DATE(2014,2,1))*('Raw Data'!$D$5:$D$64<DATE(2014,2+1,1))*'Raw Data'!$E$5:$E$64)+SUMPRODUCT(('Raw Data'!$D$5:$D$64>=DATE(2017,2,1))*('Raw Data'!$D$5:$D$64<DATE(2017,2+1,1))*'Raw Data'!$E$5:$E$64) -> 0 | C7: Q2 | D7: =SUM(B9:B11) -> 4681.256
A8: Mar | B8: =SUMPRODUCT(('Raw Data'!$D$5:$D$64>=DATE(2016,3,1))*('Raw Data'!$D$5:$D$64<DATE(2016,3+1,1))*'Raw Data'!$E$5:$E$64)+SUMPRODUCT(('Raw Data'!$D$5:$D$64>=DATE(2015,3,1))*('Raw Data'!$D$5:$D$64<DATE(2015,3+1,1))*'Raw Data'!$E$5:$E$64)+SUMPRODUCT(('Raw Data'!$D$5:$D$64>=DATE(2014,3,1))*('Raw Data'!$D$5:$D$64<DATE(2014,3+1,1))*'Raw Data'!$E$5:$E$64)+SUMPRODUCT(('Raw Data'!$D$5:$D$64>=DATE(2017,3,1))*('Raw Data'!$D$5:$D$64<DATE(2017,3+1,1))*'Raw Data'!$E$5:$E$64) -> 63.44 | C8: Q3 | D8: =SUM(B12:B14) -> 5010.86
A9: Apr | B9: =SUMPRODUCT(('Raw Data'!$D$5:$D$64>=DATE(2016,4,1))*('Raw Data'!$D$5:$D$64<DATE(2016,4+1,1))*'Raw Data'!$E$5:$E$64)+SUMPRODUCT(('Raw Data'!$D$5:$D$64>=DATE(2015,4,1))*('Raw Data'!$D$5:$D$64<DATE(2015,4+1,1))*'Raw Data'!$E$5:$E$64)+SUMPRODUCT(('Raw Data'!$D$5:$D$64>=DATE(2014,4,1))*('Raw Data'!$D$5:$D$64<DATE(2014,4+1,1))*'Raw Data'!$E$5:$E$64)+SUMPRODUCT(('Raw Data'!$D$5:$D$64>=DATE(2017,4,1))*('Raw Data'!$D$5:$D$64<DATE(2017,4+1,1))*'Raw Data'!$E$5:$E$64) -> 225.102 | C9: Q4 | D9: =SUM(B15:B17) -> 7002.9147
A10: May | B10: =SUMPRODUCT(('Raw Data'!$D$5:$D$64>=DATE(2016,5,1))*('Raw Data'!$D$5:$D$64<DATE(2016,5+1,1))*'Raw Data'!$E$5:$E$64)+SUMPRODUCT(('Raw Data'!$D$5:$D$64>=DATE(2015,5,1))*('Raw Data'!$D$5:$D$64<DATE(2015,5+1,1))*'Raw Data'!$E$5:$E$64)+SUMPRODUCT(('Raw Data'!$D$5:$D$64>=DATE(2014,5,1))*('Raw Data'!$D$5:$D$64<DATE(2014,5+1,1))*'Raw Data'!$E$5:$E$64)+SUMPRODUCT(('Raw Data'!$D$5:$D$64>=DATE(2017,5,1))*('Raw Data'!$D$5:$D$64<DATE(2017,5+1,1))*'Raw Data'!$E$5:$E$64) -> 55.5
A11: Jun | B11: =SUMPRODUCT(('Raw Data'!$D$5:$D$64>=DATE(2016,6,1))*('Raw Data'!$D$5:$D$64<DATE(2016,6+1,1))*'Raw Data'!$E$5:$E$64)+SUMPRODUCT(('Raw Data'!$D$5:$D$64>=DATE(2015,6,1))*('Raw Data'!$D$5:$D$64<DATE(2015,6+1,1))*'Raw Data'!$E$5:$E$64)+SUMPRODUCT(('Raw Data'!$D$5:$D$64>=DATE(2014,6,1))*('Raw Data'!$D$5:$D$64<DATE(2014,6+1,1))*'Raw Data'!$E$5:$E$64)+SUMPRODUCT(('Raw Data'!$D$5:$D$64>=DATE(2017,6,1))*('Raw Data'!$D$5:$D$64<DATE(2017,6+1,1))*'Raw Data'!$E$5:$E$64) -> 4400.654
A12: Jul | B12: =SUMPRODUCT(('Raw Data'!$D$5:$D$64>=DATE(2016,7,1))*('Raw Data'!$D$5:$D$64<DATE(2016,7+1,1))*'Raw Data'!$E$5:$E$64)+SUMPRODUCT(('Raw Data'!$D$5:$D$64>=DATE(2015,7,1))*('Raw Data'!$D$5:$D$64<DATE(2015,7+1,1))*'Raw Data'!$E$5:$E$64)+SUMPRODUCT(('Raw Data'!$D$5:$D$64>=DATE(2014,7,1))*('Raw Data'!$D$5:$D$64<DATE(2014,7+1,1))*'Raw Data'!$E$5:$E$64)+SUMPRODUCT(('Raw Data'!$D$5:$D$64>=DATE(2017,7,1))*('Raw Data'!$D$5:$D$64<DATE(2017,7+1,1))*'Raw Data'!$E$5:$E$64) -> 149.252
A13: Aug | B13: =SUMPRODUCT(('Raw Data'!$D$5:$D$64>=DATE(2016,8,1))*('Raw Data'!$D$5:$D$64<DATE(2016,8+1,1))*'Raw Data'!$E$5:$E$64)+SUMPRODUCT(('Raw Data'!$D$5:$D$64>=DATE(2015,8,1))*('Raw Data'!$D$5:$D$64<DATE(2015,8+1,1))*'Raw Data'!$E$5:$E$64)+SUMPRODUCT(('Raw Data'!$D$5:$D$64>=DATE(2014,8,1))*('Raw Data'!$D$5:$D$64<DATE(2014,8+1,1))*'Raw Data'!$E$5:$E$64)+SUMPRODUCT(('Raw Data'!$D$5:$D$64>=DATE(2017,8,1))*('Raw Data'!$D$5:$D$64<DATE(2017,8+1,1))*'Raw Data'!$E$5:$E$64) -> 244.76
A14: Sep | B14: =SUMPRODUCT(('Raw Data'!$D$5:$D$64>=DATE(2016,9,1))*('Raw Data'!$D$5:$D$64<DATE(2016,9+1,1))*'Raw Data'!$E$5:$E$64)+SUMPRODUCT(('Raw Data'!$D$5:$D$64>=DATE(2015,9,1))*('Raw Data'!$D$5:$D$64<DATE(2015,9+1,1))*'Raw Data'!$E$5:$E$64)+SUMPRODUCT(('Raw Data'!$D$5:$D$64>=DATE(2014,9,1))*('Raw Data'!$D$5:$D$64<DATE(2014,9+1,1))*'Raw Data'!$E$5:$E$64)+SUMPRODUCT(('Raw Data'!$D$5:$D$64>=DATE(2017,9,1))*('Raw Data'!$D$5:$D$64<DATE(2017,9+1,1))*'Raw Data'!$E$5:$E$64) -> 4616.848
A15: Oct | B15: =SUMPRODUCT(('Raw Data'!$D$5:$D$64>=DATE(2016,10,1))*('Raw Data'!$D$5:$D$64<DATE(2016,10+1,1))*'Raw Data'!$E$5:$E$64)+SUMPRODUCT(('Raw Data'!$D$5:$D$64>=DATE(2015,10,1))*('Raw Data'!$D$5:$D$64<DATE(2015,10+1,1))*'Raw Data'!$E$5:$E$64)+SUMPRODUCT(('Raw Data'!$D$5:$D$64>=DATE(2014,10,1))*('Raw Data'!$D$5:$D$64<DATE(2014,10+1,1))*'Raw Data'!$E$5:$E$64)+SUMPRODUCT(('Raw Data'!$D$5:$D$64>=DATE(2017,10,1))*('Raw Data'!$D$5:$D$64<DATE(2017,10+1,1))*'Raw Data'!$E$5:$E$64) -> 1221.3775
A16: Nov | B16: =SUMPRODUCT(('Raw Data'!$D$5:$D$64>=DATE(2016,11,1))*('Raw Data'!$D$5:$D$64<DATE(2016,11+1,1))*'Raw Data'!$E$5:$E$64)+SUMPRODUCT(('Raw Data'!$D$5:$D$64>=DATE(2015,11,1))*('Raw Data'!$D$5:$D$64<DATE(2015,11+1,1))*'Raw Data'!$E$5:$E$64)+SUMPRODUCT(('Raw Data'!$D$5:$D$64>=DATE(2014,11,1))*('Raw Data'!$D$5:$D$64<DATE(2014,11+1,1))*'Raw Data'!$E$5:$E$64)+SUMPRODUCT(('Raw Data'!$D$5:$D$64>=DATE(2017,11,1))*('Raw Data'!$D$5:$D$64<DATE(2017,11+1,1))*'Raw Data'!$E$5:$E$64) -> 1731.134
A17: Dec | B17: =SUMPRODUCT(('Raw Data'!$D$5:$D$64>=DATE(2016,12,1))*('Raw Data'!$D$5:$D$64<DATE(2016,12+1,1))*'Raw Data'!$E$5:$E$64)+SUMPRODUCT(('Raw Data'!$D$5:$D$64>=DATE(2015,12,1))*('Raw Data'!$D$5:$D$64<DATE(2015,12+1,1))*'Raw Data'!$E$5:$E$64)+SUMPRODUCT(('Raw Data'!$D$5:$D$64>=DATE(2014,12,1))*('Raw Data'!$D$5:$D$64<DATE(2014,12+1,1))*'Raw Data'!$E$5:$E$64)+SUMPRODUCT(('Raw Data'!$D$5:$D$64>=DATE(2017,12,1))*('Raw Data'!$D$5:$D$64<DATE(2017,12+1,1))*'Raw Data'!$E$5:$E$64) -> 4050.4032
A19: Tasks 2 & 4: Multiple tables — Sales by Category (Table A) and Profit by Region (Table B)
A20: Category | B20: Sum of Sales | D20: Region | E20: Sum of Profit
A21: Furniture | B21: =SUMIFS('Raw Data'!$E$5:$E$64,'Raw Data'!$B$5:$B$64,A21) -> 9381.0907 | D21: Central | E21: =SUMIFS('Raw Data'!$F$5:$F$64,'Raw Data'!$C$5:$C$64,D21) -> 28.2028
A22: Office Supplies | B22: =SUMIFS('Raw Data'!$E$5:$E$64,'Raw Data'!$B$5:$B$64,A22) -> 2568.362 | D22: East | E22: =SUMIFS('Raw Data'!$F$5:$F$64,'Raw Data'!$C$5:$C$64,D22) -> -1540.8538
A23: Technology | B23: =SUMIFS('Raw Data'!$E$5:$E$64,'Raw Data'!$B$5:$B$64,A23) -> 4911.236 | D23: South | E23: =SUMIFS('Raw Data'!$F$5:$F$64,'Raw Data'!$C$5:$C$64,D23) -> -113.5758
D24: West | E24: =SUMIFS('Raw Data'!$F$5:$F$64,'Raw Data'!$C$5:$C$64,D24) -> 650.9459

Sheet 3. Date & Blank Grouping
A1: Section 7.3 — Pivot Table for Grouping Via Date, Blank Cells
A2: Tasks 1-5: Group by date, Handle blanks, Impact of blanks, Different date formats, Importance of managing blanks
A4: Task 1 & 4: Sales grouped by Year, shown in two different date-format groupings
A5: Year | B5: Sum of Sales | C5: Year-Quarter (alt. format) | D5: Sum of Sales
A6: 2014 | B6: =SUMIFS('Raw Data'!$E$5:$E$64,'Raw Data'!$D$5:$D$64,">="&DATE(2014,1,1),'Raw Data'!$D$5:$D$64,"<"&DATE(2014+1,1,1)) -> 4892.404 | C6: 2014-Q1 | D6: =SUMIFS('Raw Data'!$E$5:$E$64,'Raw Data'!$D$5:$D$64,">="&DATE(2014,1,1),'Raw Data'!$D$5:$D$64,"<"&DATE(2014,1+3,1)) -> 0
A7: 2015 | B7: =SUMIFS('Raw Data'!$E$5:$E$64,'Raw Data'!$D$5:$D$64,">="&DATE(2015,1,1),'Raw Data'!$D$5:$D$64,"<"&DATE(2015+1,1,1)) -> 6863.8667 | C7: 2014-Q2 | D7: =SUMIFS('Raw Data'!$E$5:$E$64,'Raw Data'!$D$5:$D$64,">="&DATE(2014,4,1),'Raw Data'!$D$5:$D$64,"<"&DATE(2014,4+3,1)) -> 3769.804
A8: 2016 | B8: =SUMIFS('Raw Data'!$E$5:$E$64,'Raw Data'!$D$5:$D$64,">="&DATE(2016,1,1),'Raw Data'!$D$5:$D$64,"<"&DATE(2016+1,1,1)) -> 4745.238 | C8: 2014-Q3 | D8: =SUMIFS('Raw Data'!$E$5:$E$64,'Raw Data'!$D$5:$D$64,">="&DATE(2014,7,1),'Raw Data'!$D$5:$D$64,"<"&DATE(2014,7+3,1)) -> 244.76
A9: 2017 | B9: =SUMIFS('Raw Data'!$E$5:$E$64,'Raw Data'!$D$5:$D$64,">="&DATE(2017,1,1),'Raw Data'!$D$5:$D$64,"<"&DATE(2017+1,1,1)) -> 359.18 | C9: 2014-Q4 | D9: =SUMIFS('Raw Data'!$E$5:$E$64,'Raw Data'!$D$5:$D$64,">="&DATE(2014,10,1),'Raw Data'!$D$5:$D$64,"<"&DATE(2014,10+3,1)) -> 877.84
C10: 2015-Q1 | D10: =SUMIFS('Raw Data'!$E$5:$E$64,'Raw Data'!$D$5:$D$64,">="&DATE(2015,1,1),'Raw Data'!$D$5:$D$64,"<"&DATE(2015,1+3,1)) -> 0
C11: 2015-Q2 | D11: =SUMIFS('Raw Data'!$E$5:$E$64,'Raw Data'!$D$5:$D$64,">="&DATE(2015,4,1),'Raw Data'!$D$5:$D$64,"<"&DATE(2015,4+3,1)) -> 209.55
C12: 2015-Q3 | D12: =SUMIFS('Raw Data'!$E$5:$E$64,'Raw Data'!$D$5:$D$64,">="&DATE(2015,7,1),'Raw Data'!$D$5:$D$64,"<"&DATE(2015,7+3,1)) -> 4374.064
C13: 2015-Q4 | D13: =SUMIFS('Raw Data'!$E$5:$E$64,'Raw Data'!$D$5:$D$64,">="&DATE(2015,10,1),'Raw Data'!$D$5:$D$64,"<"&DATE(2015,10+3,1)) -> 2280.2527
A15: Tasks 2-3: Handling blank Region cells — grouped total including a "(blank)" bucket
A16: Region (Row Labels) | B16: Sum of Sales | C16: Count of Orders
A17: Central | B17: =SUMIFS('Raw Data'!$E$5:$E$64,'Raw Data'!$C$5:$C$64,A17) -> 3976.5812 | C17: =COUNTIFS('Raw Data'!$C$5:$C$64,A17) -> 19
A18: East | B18: =SUMIFS('Raw Data'!$E$5:$E$64,'Raw Data'!$C$5:$C$64,A18) -> 4080.938 | C18: =COUNTIFS('Raw Data'!$C$5:$C$64,A18) -> 15
A19: South | B19: =SUMIFS('Raw Data'!$E$5:$E$64,'Raw Data'!$C$5:$C$64,A19) -> 1989.3975 | C19: =COUNTIFS('Raw Data'!$C$5:$C$64,A19) -> 5
A20: West | B20: =SUMIFS('Raw Data'!$E$5:$E$64,'Raw Data'!$C$5:$C$64,A20) -> 3955.704 | C20: =COUNTIFS('Raw Data'!$C$5:$C$64,A20) -> 16
A21: (blank) | B21: =SUMIFS('Raw Data'!$E$5:$E$64,'Raw Data'!$C$5:$C$64,"") -> 2858.068 | C21: =COUNTIFS('Raw Data'!$C$5:$C$64,"") -> 5

Sheet 4. Custom Grouping & CF
A1: Section 7.4 — Custom Grouping, Conditional Formatting in Pivot Table
A2: Tasks 1-5: Custom groups, Conditional formatting, Different CF rules, Detailed analysis, Benefits
A4: Task 1 & 4: Custom group — Categories combined into a business-defined "Product Group"
A5: Product Group (custom) | B5: Categories Included | C5: Sum of Sales | D5: Sum of Profit
A6: Hard Goods | B6: Furniture, Technology | C6: =SUMIFS('Raw Data'!$E$5:$E$64,'Raw Data'!$B$5:$B$64,"Furniture")+SUMIFS('Raw Data'!$E$5:$E$64,'Raw Data'!$B$5:$B$64,"Technology") -> 14292.327 | D6: =SUMIFS('Raw Data'!$F$5:$F$64,'Raw Data'!$B$5:$B$64,"Furniture")+SUMIFS('Raw Data'!$F$5:$F$64,'Raw Data'!$B$5:$B$64,"Technology") -> -913.8177
A7: Consumables | B7: Office Supplies | C7: =SUMIFS('Raw Data'!$E$5:$E$64,'Raw Data'!$B$5:$B$64,"Office Supplies") -> 2568.362 | D7: =SUMIFS('Raw Data'!$F$5:$F$64,'Raw Data'!$B$5:$B$64,"Office Supplies") -> 331.4377
A9: Tasks 2-3: Conditional formatting applied to a PivotTable-style report — color scale, data bars, icon set
A10: Product Name | B10: Sum of Sales (Color Scale) | C10: Sum of Sales (Data Bar) | D10: Sum of Sales (Icon Set)
A11: Bush Somerset Collection Boo | B11: 261.96 | C11: 261.96 | D11: 261.96
A12: Hon Deluxe Fabric Upholstere | B12: 731.94 | C12: 731.94 | D12: 731.94
A13: Self-Adhesive Address Labels | B13: 14.62 | C13: 14.62 | D13: 14.62
A14: Bretford CR4500 Series Slim | B14: 957.5775 | C14: 957.5775 | D14: 957.5775
A15: Eldon Fold 'N Roll Cart Syst | B15: 22.368 | C15: 22.368 | D15: 22.368
A16: Eldon Expressions Wood and P | B16: 48.86 | C16: 48.86 | D16: 48.86
A17: Newell 322 | B17: 7.28 | C17: 7.28 | D17: 7.28
A18: Mitel 5320 IP Phone VoIP pho | B18: 907.152 | C18: 907.152 | D18: 907.152
A19: DXL Angle-View Binders with | B19: 18.504 | C19: 18.504 | D19: 18.504
A20: Belkin F5C206VTEL 6 Outlet S | B20: 114.9 | C20: 114.9 | D20: 114.9
A21: Chromcraft Rectangular Confe | B21: 1706.184 | C21: 1706.184 | D21: 1706.184
A22: Konftel 250 Conference phone | B22: 911.424 | C22: 911.424 | D22: 911.424
